<?xml version="1.0" ?>
<robot name="simple_cuboid_4727g">
<link name="base_link">
  <inertial>
    <origin rpy="0 0 0" xyz="0.0 0.0 0.06000000000000001"/>
    <mass value="3.7505087999999995"/>
    <inertia ixx="0.021034" ixy="-0.0" ixz="-0.0" iyy="0.011722" iyz="0.0" izz="0.023754"/>
  </inertial>
  <visual>
    <origin rpy="0 0 0" xyz="0 0 0"/>
    <geometry>
      <mesh filename="bin_stl/base_link_m-binary.stl"/>
    </geometry>
    <material name="silver">
      <color rgba="1 0 0 1"/>
    </material>
  </visual>
  <collision>
    <origin rpy="0 0 0" xyz="0 0 0"/>
    <geometry>
      <mesh filename="bin_stl/base_link_m-binary.stl"/>
    </geometry>
  </collision>
</link>
<link name="BL_1">
  <inertial>
    <origin rpy="0 0 0" xyz="-0.016000000000000014 1.3877787807814457e-17 -6.938893903907228e-18"/>
    <mass value="0.24429024474314232"/>
    <inertia ixx="0.00011" ixy="0.0" ixz="0.0" iyy="7.6e-05" iyz="0.0" izz="7.6e-05"/>
  </inertial>
  <visual>
    <origin rpy="0 0 0" xyz="0.094 -0.1 -0.015"/>
    <geometry>
      <mesh filename="bin_stl/BL_1_m-binary.stl"/>
    </geometry>
    <material name="silver">
      <color rgba="1 0 0 1"/>
    </material>
  </visual>
  <collision>
    <origin rpy="0 0 0" xyz="0.094 -0.1 -0.015"/>
    <geometry>
      <mesh filename="bin_stl/BL_1_m-binary.stl"/>
    </geometry>
  </collision>
</link>
<link name="BR_1">
  <inertial>
    <origin rpy="0 0 0" xyz="0.015999999999999986 1.3877787807814457e-17 -6.938893903907228e-18"/>
    <mass value="0.24429024474314232"/>
    <inertia ixx="0.00011" ixy="0.0" ixz="0.0" iyy="7.6e-05" iyz="0.0" izz="7.6e-05"/>
  </inertial>
  <visual>
    <origin rpy="0 0 0" xyz="-0.094 -0.1 -0.015"/>
    <geometry>
      <mesh filename="bin_stl/BR_1_m-binary.stl"/>
    </geometry>
    <material name="silver">
      <color rgba="1 0 0 1"/>
    </material>
  </visual>
  <collision>
    <origin rpy="0 0 0" xyz="-0.094 -0.1 -0.015"/>
    <geometry>
      <mesh filename="bin_stl/BR_1_m-binary.stl"/>
    </geometry>
  </collision>
</link>
<link name="FR_1">
  <inertial>
    <origin rpy="0 0 0" xyz="0.015999999999999986 2.7755575615628914e-17 2.0816681711721685e-17"/>
    <mass value="0.24429024474314232"/>
    <inertia ixx="0.00011" ixy="0.0" ixz="0.0" iyy="7.6e-05" iyz="0.0" izz="7.6e-05"/>
  </inertial>
  <visual>
    <origin rpy="0 0 0" xyz="-0.094 0.1 -0.015"/>
    <geometry>
      <mesh filename="bin_stl/FR_1_m-binary.stl"/>
    </geometry>
    <material name="silver">
      <color rgba="1 0 0 1"/>
    </material>
  </visual>
  <collision>
    <origin rpy="0 0 0" xyz="-0.094 0.1 -0.015"/>
    <geometry>
      <mesh filename="bin_stl/FR_1_m-binary.stl"/>
    </geometry>
  </collision>
</link>
<link name="FL_1">
  <inertial>
    <origin rpy="0 0 0" xyz="-0.016000000000000014 2.7755575615628914e-17 1.9081958235744878e-17"/>
    <mass value="0.24429024474314232"/>
    <inertia ixx="0.00011" ixy="-0.0" ixz="0.0" iyy="7.6e-05" iyz="0.0" izz="7.6e-05"/>
  </inertial>
  <visual>
    <origin rpy="0 0 0" xyz="0.094 0.1 -0.015"/>
    <geometry>
      <mesh filename="bin_stl/FL_1_m-binary.stl"/>
    </geometry>
    <material name="silver">
      <color rgba="1 0 0 1"/>
    </material>
  </visual>
  <collision>
    <origin rpy="0 0 0" xyz="0.094 0.1 -0.015"/>
    <geometry>
      <mesh filename="bin_stl/FL_1_m-binary.stl"/>
    </geometry>
  </collision>
</link>
<joint name="BL" type="continuous">
  <origin rpy="0 0 0" xyz="-0.094 0.1 0.015"/>
  <parent link="base_link"/>
  <child link="BL_1"/>
  <axis xyz="-1.0 0.0 0.0"/>
</joint>
<transmission name="BL_tran">
  <type>transmission_interface/SimpleTransmission</type>
  <joint name="BL">
    <hardwareInterface>PositionJointInterface</hardwareInterface>
  </joint>
  <actuator name="BL_actr">
    <hardwareInterface>PositionJointInterface</hardwareInterface>
    <mechanicalReduction>1</mechanicalReduction>
  </actuator>
</transmission>
<joint name="BR" type="continuous">
  <origin rpy="0 0 0" xyz="0.094 0.1 0.015"/>
  <parent link="base_link"/>
  <child link="BR_1"/>
  <axis xyz="-1.0 0.0 0.0"/>
</joint>
<transmission name="BR_tran">
  <type>transmission_interface/SimpleTransmission</type>
  <joint name="BR">
    <hardwareInterface>PositionJointInterface</hardwareInterface>
  </joint>
  <actuator name="BR_actr">
    <hardwareInterface>PositionJointInterface</hardwareInterface>
    <mechanicalReduction>1</mechanicalReduction>
  </actuator>
</transmission>
<joint name="FR" type="continuous">
  <origin rpy="0 0 0" xyz="0.094 -0.1 0.015"/>
  <parent link="base_link"/>
  <child link="FR_1"/>
  <axis xyz="-1.0 0.0 0.0"/>
</joint>
<transmission name="FR_tran">
  <type>transmission_interface/SimpleTransmission</type>
  <joint name="FR">
    <hardwareInterface>PositionJointInterface</hardwareInterface>
  </joint>
  <actuator name="FR_actr">
    <hardwareInterface>PositionJointInterface</hardwareInterface>
    <mechanicalReduction>1</mechanicalReduction>
  </actuator>
</transmission>
<joint name="FL" type="continuous">
  <origin rpy="0 0 0" xyz="-0.094 -0.1 0.015"/>
  <parent link="base_link"/>
  <child link="FL_1"/>
  <axis xyz="-1.0 0.0 0.0"/>
</joint>
<transmission name="FL_tran">
  <type>transmission_interface/SimpleTransmission</type>
  <joint name="FL">
    <hardwareInterface>PositionJointInterface</hardwareInterface>
  </joint>
  <actuator name="FL_actr">
    <hardwareInterface>PositionJointInterface</hardwareInterface>
    <mechanicalReduction>1</mechanicalReduction>
  </actuator>
</transmission>
<gazebo>
  <plugin filename="libgazebo_ros_control.so" name="control"/>
</gazebo>
</robot>
