<?xml version="1.0" ?>
<robot name="sc_2553_50mm">
  <material name="blue">
    <color rgba="0 0 0.8 1"/>
  </material>

  <material name="white">
    <color rgba="1 1 1 1"/>
  </material>

  <material name="black">
    <color rgba="0 0 0 1"/>
  </material>

  <material name="green">
    <color rgba="0 0.8 0 1"/>
  </material>

  <material name="red">
    <color rgba="0.8 0 0 1"/>
  </material>

  <material name="yellow">
    <color rgba="0.8 0.8 0 1"/>
  </material>
<link name="base_link">
  <inertial>
    <origin rpy="0 0 0" xyz="0.0 0.0 0.030000000000000006"/>
    <mass value="1.8752543999999998"/>
    <inertia ixx="0.008829322800000003" ixy="-2.842170943040401e-18" ixz="0.0" iyy="0.004173066124800003" iyz="1.4210854715202004e-18" izz="0.0118772362848"/>
  </inertial>
  <visual>
    <origin rpy="0 0 0" xyz="0 0 0"/>
    <geometry>
      <mesh filename="bin_stl/base_link_m-binary.stl"/>
    </geometry>
    <material name="white"/>
  </visual>
  <collision>
    <origin rpy="0 0 0" xyz="0 0 0"/>
    <geometry>
      <mesh filename="bin_stl/base_link_m-binary.stl"/>
    </geometry>
  </collision>
</link>
<link name="BL_1">
  <inertial>
    <origin rpy="0 0 0" xyz="-0.016000000000000014 0.0 -8.673617379884035e-18"/>
    <mass value="0.16964600329384877"/>
    <inertia ixx="5.3014376029326266e-05" ixy="-2.168404344971009e-19" ixz="5.421010862427522e-20" iyy="4.098364696240517e-05" iyz="5.421010862427522e-20" izz="4.0983646962406035e-05"/>
  </inertial>
  <visual>
    <origin rpy="0 0 0" xyz="0.094 -0.1 -0.015"/>
    <geometry>
      <mesh filename="bin_stl/BL_1_m-binary.stl"/>
    </geometry>
    <material name="yellow"/>
  </visual>
  <collision>
    <origin rpy="0 0 0" xyz="0.094 -0.1 -0.015"/>
    <geometry>
      <mesh filename="bin_stl/BL_1_m-binary.stl"/>
    </geometry>
  </collision>
</link>
<link name="BR_1">
  <inertial>
    <origin rpy="0 0 0" xyz="0.015999999999999986 0.0 -1.5612511283791264e-17"/>
    <mass value="0.16964600329384888"/>
    <inertia ixx="5.30143760293267e-05" ixy="0.0" ixz="-5.421010862427522e-20" iyy="4.09836469624043e-05" iyz="-5.421010862427522e-20" izz="4.098364696240517e-05"/>
  </inertial>
  <visual>
    <origin rpy="0 0 0" xyz="-0.094 -0.1 -0.015"/>
    <geometry>
      <mesh filename="bin_stl/BR_1_m-binary.stl"/>
    </geometry>
    <material name="blue"/>
  </visual>
  <collision>
    <origin rpy="0 0 0" xyz="-0.094 -0.1 -0.015"/>
    <geometry>
      <mesh filename="bin_stl/BR_1_m-binary.stl"/>
    </geometry>
  </collision>
</link>
<link name="FR_1">
  <inertial>
    <origin rpy="0 0 0" xyz="0.015999999999999986 0.0 1.9081958235744878e-17"/>
    <mass value="0.16964600329384877"/>
    <inertia ixx="5.301437602932605e-05" ixy="-2.168404344971009e-19" ixz="0.0" iyy="4.098364696240387e-05" iyz="0.0" izz="4.098364696240517e-05"/>
  </inertial>
  <visual>
    <origin rpy="0 0 0" xyz="-0.094 0.1 -0.015"/>
    <geometry>
      <mesh filename="bin_stl/FR_1_m-binary.stl"/>
    </geometry>
    <material name="red"/>
  </visual>
  <collision>
    <origin rpy="0 0 0" xyz="-0.094 0.1 -0.015"/>
    <geometry>
      <mesh filename="bin_stl/FR_1_m-binary.stl"/>
    </geometry>
  </collision>
</link>
<link name="FL_1">
  <inertial>
    <origin rpy="0 0 0" xyz="-0.016000000000000014 0.0 1.5612511283791264e-17"/>
    <mass value="0.16964600329384877"/>
    <inertia ixx="5.301437602932605e-05" ixy="2.168404344971009e-19" ixz="5.421010862427522e-20" iyy="4.0983646962404734e-05" iyz="0.0" izz="4.0983646962406035e-05"/>
  </inertial>
  <visual>
    <origin rpy="0 0 0" xyz="0.094 0.1 -0.015"/>
    <geometry>
      <mesh filename="bin_stl/FL_1_m-binary.stl"/>
    </geometry>
    <material name="green"/>
  </visual>
  <collision>
    <origin rpy="0 0 0" xyz="0.094 0.1 -0.015"/>
    <geometry>
      <mesh filename="bin_stl/FL_1_m-binary.stl"/>
    </geometry>
  </collision>
</link>
<joint name="BL" type="continuous">
  <origin rpy="0 0 0" xyz="-0.094 0.1 0.015"/>
  <parent link="base_link"/>
  <child link="BL_1"/>
  <axis xyz="-1.0 0.0 0.0"/>
</joint>
<transmission name="BL_tran">
  <type>transmission_interface/SimpleTransmission</type>
  <joint name="BL">
    <hardwareInterface>PositionJointInterface</hardwareInterface>
  </joint>
  <actuator name="BL_actr">
    <hardwareInterface>PositionJointInterface</hardwareInterface>
    <mechanicalReduction>1</mechanicalReduction>
  </actuator>
</transmission>
<joint name="BR" type="continuous">
  <origin rpy="0 0 0" xyz="0.094 0.1 0.015"/>
  <parent link="base_link"/>
  <child link="BR_1"/>
  <axis xyz="-1.0 0.0 0.0"/>
</joint>
<transmission name="BR_tran">
  <type>transmission_interface/SimpleTransmission</type>
  <joint name="BR">
    <hardwareInterface>PositionJointInterface</hardwareInterface>
  </joint>
  <actuator name="BR_actr">
    <hardwareInterface>PositionJointInterface</hardwareInterface>
    <mechanicalReduction>1</mechanicalReduction>
  </actuator>
</transmission>
<joint name="FR" type="continuous">
  <origin rpy="0 0 0" xyz="0.094 -0.1 0.015"/>
  <parent link="base_link"/>
  <child link="FR_1"/>
  <axis xyz="1.0 0.0 0.0"/>
</joint>
<transmission name="FR_tran">
  <type>transmission_interface/SimpleTransmission</type>
  <joint name="FR">
    <hardwareInterface>PositionJointInterface</hardwareInterface>
  </joint>
  <actuator name="FR_actr">
    <hardwareInterface>PositionJointInterface</hardwareInterface>
    <mechanicalReduction>1</mechanicalReduction>
  </actuator>
</transmission>
<joint name="FL" type="continuous">
  <origin rpy="0 0 0" xyz="-0.094 -0.1 0.015"/>
  <parent link="base_link"/>
  <child link="FL_1"/>
  <axis xyz="-1.0 0.0 0.0"/>
</joint>
<transmission name="FL_tran">
  <type>transmission_interface/SimpleTransmission</type>
  <joint name="FL">
    <hardwareInterface>PositionJointInterface</hardwareInterface>
  </joint>
  <actuator name="FL_actr">
    <hardwareInterface>PositionJointInterface</hardwareInterface>
    <mechanicalReduction>1</mechanicalReduction>
  </actuator>
</transmission>
<gazebo>
  <plugin filename="libgazebo_ros_control.so" name="control"/>
</gazebo>
</robot>
